<?xml version='1.0' encoding='utf-8'?>
<robot name="g1_29dof_with_hand">
  <link name="pelvis">
    </link>
  <link name="pelvis_contour_link">
    </link>
  <joint name="pelvis_contour_joint" type="fixed">
    <parent link="pelvis" />
    <child link="pelvis_contour_link" />
  </joint>
  <link name="left_hip_pitch_link">
    </link>
  <joint name="left_hip_pitch_joint" type="revolute">
    <origin xyz="0 0.064452 -0.1027" rpy="0 0 0" />
    <parent link="pelvis" />
    <child link="left_hip_pitch_link" />
    <axis xyz="0 1 0" />
    <limit lower="-2.5307" upper="2.8798" effort="88" velocity="32" />
  </joint>
  <link name="left_hip_roll_link">
    </link>
  <joint name="left_hip_roll_joint" type="revolute">
    <origin xyz="0 0.052 -0.030465" rpy="0 -0.1749 0" />
    <parent link="left_hip_pitch_link" />
    <child link="left_hip_roll_link" />
    <axis xyz="1 0 0" />
    <limit lower="-0.5236" upper="2.9671" effort="88" velocity="32" />
  </joint>
  <link name="left_hip_yaw_link">
    </link>
  <joint name="left_hip_yaw_joint" type="revolute">
    <origin xyz="0.025001 0 -0.12412" rpy="0 0 0" />
    <parent link="left_hip_roll_link" />
    <child link="left_hip_yaw_link" />
    <axis xyz="0 0 1" />
    <limit lower="-2.7576" upper="2.7576" effort="88" velocity="32" />
  </joint>
  <link name="left_knee_link">
    </link>
  <joint name="left_knee_joint" type="revolute">
    <origin xyz="-0.078273 0.0021489 -0.17734" rpy="0 0.1749 0" />
    <parent link="left_hip_yaw_link" />
    <child link="left_knee_link" />
    <axis xyz="0 1 0" />
    <limit lower="-0.087267" upper="2.8798" effort="139" velocity="20" />
  </joint>
  <link name="left_ankle_pitch_link">
    </link>
  <joint name="left_ankle_pitch_joint" type="revolute">
    <origin xyz="0 -9.4445E-05 -0.30001" rpy="0 0 0" />
    <parent link="left_knee_link" />
    <child link="left_ankle_pitch_link" />
    <axis xyz="0 1 0" />
    <limit lower="-0.87267" upper="0.5236" effort="35" velocity="30" />
  </joint>
  <link name="left_ankle_roll_link">
    </link>
  <joint name="left_ankle_roll_joint" type="revolute">
    <origin xyz="0 0 -0.017558" rpy="0 0 0" />
    <parent link="left_ankle_pitch_link" />
    <child link="left_ankle_roll_link" />
    <axis xyz="1 0 0" />
    <limit lower="-0.2618" upper="0.2618" effort="35" velocity="30" />
  </joint>
  <link name="right_hip_pitch_link">
    </link>
  <joint name="right_hip_pitch_joint" type="revolute">
    <origin xyz="0 -0.064452 -0.1027" rpy="0 0 0" />
    <parent link="pelvis" />
    <child link="right_hip_pitch_link" />
    <axis xyz="0 1 0" />
    <limit lower="-2.5307" upper="2.8798" effort="88" velocity="32" />
  </joint>
  <link name="right_hip_roll_link">
    </link>
  <joint name="right_hip_roll_joint" type="revolute">
    <origin xyz="0 -0.052 -0.030465" rpy="0 -0.1749 0" />
    <parent link="right_hip_pitch_link" />
    <child link="right_hip_roll_link" />
    <axis xyz="1 0 0" />
    <limit lower="-2.9671" upper="0.5236" effort="88" velocity="32" />
  </joint>
  <link name="right_hip_yaw_link">
    </link>
  <joint name="right_hip_yaw_joint" type="revolute">
    <origin xyz="0.025001 0 -0.12412" rpy="0 0 0" />
    <parent link="right_hip_roll_link" />
    <child link="right_hip_yaw_link" />
    <axis xyz="0 0 1" />
    <limit lower="-2.7576" upper="2.7576" effort="88" velocity="32" />
  </joint>
  <link name="right_knee_link">
    </link>
  <joint name="right_knee_joint" type="revolute">
    <origin xyz="-0.078273 -0.0021489 -0.17734" rpy="0 0.1749 0" />
    <parent link="right_hip_yaw_link" />
    <child link="right_knee_link" />
    <axis xyz="0 1 0" />
    <limit lower="-0.087267" upper="2.8798" effort="139" velocity="20" />
  </joint>
  <link name="right_ankle_pitch_link">
    </link>
  <joint name="right_ankle_pitch_joint" type="revolute">
    <origin xyz="0 9.4445E-05 -0.30001" rpy="0 0 0" />
    <parent link="right_knee_link" />
    <child link="right_ankle_pitch_link" />
    <axis xyz="0 1 0" />
    <limit lower="-0.87267" upper="0.5236" effort="35" velocity="30" />
  </joint>
  <link name="right_ankle_roll_link">
    </link>
  <joint name="right_ankle_roll_joint" type="revolute">
    <origin xyz="0 0 -0.017558" rpy="0 0 0" />
    <parent link="right_ankle_pitch_link" />
    <child link="right_ankle_roll_link" />
    <axis xyz="1 0 0" />
    <limit lower="-0.2618" upper="0.2618" effort="35" velocity="30" />
  </joint>
  <link name="waist_yaw_link">
    </link>
  <joint name="waist_yaw_joint" type="revolute">
    <origin xyz="0 0 0" rpy="0 0 0" />
    <parent link="pelvis" />
    <child link="waist_yaw_link" />
    <axis xyz="0 0 1" />
    <limit lower="-2.618" upper="2.618" effort="88" velocity="32" />
  </joint>
  <link name="waist_roll_link">
    </link>
  <joint name="waist_roll_joint" type="revolute">
    <origin xyz="-0.0039635 0 0.035" rpy="0 0 0" />
    <parent link="waist_yaw_link" />
    <child link="waist_roll_link" />
    <axis xyz="1 0 0" />
    <limit lower="-0.52" upper="0.52" effort="35" velocity="30" />
  </joint>
  <link name="torso_link">
    </link>
  <joint name="waist_pitch_joint" type="revolute">
    <origin xyz="0 0 0.019" rpy="0 0 0" />
    <parent link="waist_roll_link" />
    <child link="torso_link" />
    <axis xyz="0 1 0" />
    <limit lower="-0.52" upper="0.52" effort="35" velocity="30" />
  </joint>
  <joint name="logo_joint" type="fixed">
    <origin xyz="0.0039635 0 -0.054" rpy="0 0 0" />
    <parent link="torso_link" />
    <child link="logo_link" />
  </joint>
  <link name="logo_link">
    </link>
  <link name="head_link">
    </link>
  <joint name="head_joint" type="fixed">
    <origin xyz="0.0039635 0 -0.054" rpy="0 0 0" />
    <parent link="torso_link" />
    <child link="head_link" />
  </joint>
  <link name="waist_support_link">
    </link>
  <joint name="waist_support_joint" type="fixed">
    <origin xyz="0.0039635 0 -0.054" rpy="0 0 0" />
    <parent link="torso_link" />
    <child link="waist_support_link" />
  </joint>
  <link name="imu_in_torso" />
  <joint name="imu_in_torso_joint" type="fixed">
    <origin xyz="-0.03959 -0.00224 0.13792" rpy="0 0 0" />
    <parent link="torso_link" />
    <child link="imu_in_torso" />
  </joint>
  <link name="imu_in_pelvis" />
  <joint name="imu_in_pelvis_joint" type="fixed">
    <origin xyz="0.04525 0 -0.08339" rpy="0 0 0" />
    <parent link="pelvis" />
    <child link="imu_in_pelvis" />
  </joint>
  <link name="d435_link" />
  <joint name="d435_joint" type="fixed">
    <origin xyz="0.0576235 0.01753 0.41987" rpy="0 0.8307767239493009 0" />
    <parent link="torso_link" />
    <child link="d435_link" />
  </joint>
  <link name="mid360_link" />
  <joint name="mid360_joint" type="fixed">
    <origin xyz="0.0002835 0.00003 0.40618" rpy="0 0.04014257279586953 0" />
    <parent link="torso_link" />
    <child link="mid360_link" />
  </joint>
  <link name="left_shoulder_pitch_link">
    </link>
  <joint name="left_shoulder_pitch_joint" type="revolute">
    <origin xyz="0.0039563 0.10022 0.23778" rpy="0.27931 5.4949E-05 -0.00019159" />
    <parent link="torso_link" />
    <child link="left_shoulder_pitch_link" />
    <axis xyz="0 1 0" />
    <limit lower="-3.0892" upper="2.6704" effort="25" velocity="37" />
  </joint>
  <link name="left_shoulder_roll_link">
    </link>
  <joint name="left_shoulder_roll_joint" type="revolute">
    <origin xyz="0 0.038 -0.013831" rpy="-0.27925 0 0" />
    <parent link="left_shoulder_pitch_link" />
    <child link="left_shoulder_roll_link" />
    <axis xyz="1 0 0" />
    <limit lower="-1.5882" upper="2.2515" effort="25" velocity="37" />
  </joint>
  <link name="left_shoulder_yaw_link">
    </link>
  <joint name="left_shoulder_yaw_joint" type="revolute">
    <origin xyz="0 0.00624 -0.1032" rpy="0 0 0" />
    <parent link="left_shoulder_roll_link" />
    <child link="left_shoulder_yaw_link" />
    <axis xyz="0 0 1" />
    <limit lower="-2.618" upper="2.618" effort="25" velocity="37" />
  </joint>
  <link name="left_elbow_link">
    </link>
  <joint name="left_elbow_joint" type="revolute">
    <origin xyz="0.015783 0 -0.080518" rpy="0 0 0" />
    <parent link="left_shoulder_yaw_link" />
    <child link="left_elbow_link" />
    <axis xyz="0 1 0" />
    <limit lower="-1.0472" upper="2.0944" effort="25" velocity="37" />
  </joint>
  <joint name="left_wrist_roll_joint" type="revolute">
    <origin xyz="0.100 0.00188791 -0.010" rpy="0 0 0" />
    <axis xyz="1 0 0" />
    <parent link="left_elbow_link" />
    <child link="left_wrist_roll_link" />
    <limit effort="25" velocity="37" lower="-1.972222054" upper="1.972222054" />
  </joint>
  <link name="left_wrist_roll_link">
    </link>
  <joint name="left_wrist_pitch_joint" type="revolute">
    <origin xyz="0.038 0 0" rpy="0 0 0" />
    <axis xyz="0 1 0" />
    <parent link="left_wrist_roll_link" />
    <child link="left_wrist_pitch_link" />
    <limit effort="5" velocity="22" lower="-1.614429558" upper="1.614429558" />
  </joint>
  <link name="left_wrist_pitch_link">
    </link>
  <joint name="left_wrist_yaw_joint" type="revolute">
    <origin xyz="0.046 0 0" rpy="0 0 0" />
    <axis xyz="0 0 1" />
    <parent link="left_wrist_pitch_link" />
    <child link="left_wrist_yaw_link" />
    <limit effort="5" velocity="22" lower="-1.614429558" upper="1.614429558" />
  </joint>
  <link name="left_wrist_yaw_link">
    </link>
  <joint name="left_hand_palm_joint" type="fixed">
    <origin xyz="0.0415 0.003 0" rpy="0 0 0" />
    <parent link="left_wrist_yaw_link" />
    <child link="left_hand_palm_link" />
  </joint>
  <link name="left_hand_palm_link">
    </link>
  <joint name="left_hand_thumb_0_joint" type="revolute">
    <origin xyz="0.0255 0 0" rpy="0 0 0" />
    <axis xyz="0 1 0" />
    <parent link="left_hand_palm_link" />
    <child link="left_hand_thumb_0_link" />
    <limit effort="2.45" velocity="3.14" lower="-1.04719755" upper="1.04719755" />
  </joint>
  <link name="left_hand_thumb_0_link">
    </link>
  <joint name="left_hand_thumb_1_joint" type="revolute">
    <origin xyz="-0.0025 -0.0193 0" rpy="0 0 0" />
    <axis xyz="0 0 1" />
    <parent link="left_hand_thumb_0_link" />
    <child link="left_hand_thumb_1_link" />
    <limit effort="1.4" velocity="12" lower="-0.61086523" upper="1.04719755" />
  </joint>
  <link name="left_hand_thumb_1_link">
    </link>
  <joint name="left_hand_thumb_2_joint" type="revolute">
    <origin xyz="0 -0.0458 0" rpy="0 0 0" />
    <axis xyz="0 0 1" />
    <parent link="left_hand_thumb_1_link" />
    <child link="left_hand_thumb_2_link" />
    <limit effort="1.4" velocity="12" lower="0" upper="1.74532925" />
  </joint>
  <link name="left_hand_thumb_2_link">
    </link>
  <joint name="left_hand_middle_0_joint" type="revolute">
    <origin xyz="0.0777 0.0016 -0.0285" rpy="0 0 0" />
    <axis xyz="0 0 1" />
    <parent link="left_hand_palm_link" />
    <child link="left_hand_middle_0_link" />
    <limit effort="1.4" velocity="12" lower="-1.57079632" upper="0" />
  </joint>
  <link name="left_hand_middle_0_link">
    </link>
  <joint name="left_hand_middle_1_joint" type="revolute">
    <origin xyz="0.0458 0 0" rpy="0 0 0" />
    <axis xyz="0 0 1" />
    <parent link="left_hand_middle_0_link" />
    <child link="left_hand_middle_1_link" />
    <limit effort="1.4" velocity="12" lower="-1.74532925" upper="0" />
  </joint>
  <link name="left_hand_middle_1_link">
    </link>
  <joint name="left_hand_index_0_joint" type="revolute">
    <origin xyz="0.0777 0.0016 0.0285" rpy="0 0 0" />
    <axis xyz="0 0 1" />
    <parent link="left_hand_palm_link" />
    <child link="left_hand_index_0_link" />
    <limit effort="1.4" velocity="12" lower="-1.57079632" upper="0" />
  </joint>
  <link name="left_hand_index_0_link">
    </link>
  <joint name="left_hand_index_1_joint" type="revolute">
    <origin xyz="0.0458 0 0" rpy="0 0 0" />
    <axis xyz="0 0 1" />
    <parent link="left_hand_index_0_link" />
    <child link="left_hand_index_1_link" />
    <limit effort="1.4" velocity="12" lower="-1.74532925" upper="0" />
  </joint>
  <link name="left_hand_index_1_link">
    </link>
  <link name="right_shoulder_pitch_link">
    </link>
  <joint name="right_shoulder_pitch_joint" type="revolute">
    <origin xyz="0.0039563 -0.10021 0.23778" rpy="-0.27931 5.4949E-05 0.00019159" />
    <parent link="torso_link" />
    <child link="right_shoulder_pitch_link" />
    <axis xyz="0 1 0" />
    <limit lower="-3.0892" upper="2.6704" effort="25" velocity="37" />
  </joint>
  <link name="right_shoulder_roll_link">
    </link>
  <joint name="right_shoulder_roll_joint" type="revolute">
    <origin xyz="0 -0.038 -0.013831" rpy="0.27925 0 0" />
    <parent link="right_shoulder_pitch_link" />
    <child link="right_shoulder_roll_link" />
    <axis xyz="1 0 0" />
    <limit lower="-2.2515" upper="1.5882" effort="25" velocity="37" />
  </joint>
  <link name="right_shoulder_yaw_link">
    </link>
  <joint name="right_shoulder_yaw_joint" type="revolute">
    <origin xyz="0 -0.00624 -0.1032" rpy="0 0 0" />
    <parent link="right_shoulder_roll_link" />
    <child link="right_shoulder_yaw_link" />
    <axis xyz="0 0 1" />
    <limit lower="-2.618" upper="2.618" effort="25" velocity="37" />
  </joint>
  <link name="right_elbow_link">
    </link>
  <joint name="right_elbow_joint" type="revolute">
    <origin xyz="0.015783 0 -0.080518" rpy="0 0 0" />
    <parent link="right_shoulder_yaw_link" />
    <child link="right_elbow_link" />
    <axis xyz="0 1 0" />
    <limit lower="-1.0472" upper="2.0944" effort="25" velocity="37" />
  </joint>
  <joint name="right_wrist_roll_joint" type="revolute">
    <origin xyz="0.100 -0.00188791 -0.010" rpy="0 0 0" />
    <axis xyz="1 0 0" />
    <parent link="right_elbow_link" />
    <child link="right_wrist_roll_link" />
    <limit effort="25" velocity="37" lower="-1.972222054" upper="1.972222054" />
  </joint>
  <link name="right_wrist_roll_link">
    </link>
  <joint name="right_wrist_pitch_joint" type="revolute">
    <origin xyz="0.038 0 0" rpy="0 0 0" />
    <axis xyz="0 1 0" />
    <parent link="right_wrist_roll_link" />
    <child link="right_wrist_pitch_link" />
    <limit effort="5" velocity="22" lower="-1.614429558" upper="1.614429558" />
  </joint>
  <link name="right_wrist_pitch_link">
    </link>
  <joint name="right_wrist_yaw_joint" type="revolute">
    <origin xyz="0.046 0 0" rpy="0 0 0" />
    <axis xyz="0 0 1" />
    <parent link="right_wrist_pitch_link" />
    <child link="right_wrist_yaw_link" />
    <limit effort="5" velocity="22" lower="-1.614429558" upper="1.614429558" />
  </joint>
  <link name="right_wrist_yaw_link">
    </link>
  <joint name="right_hand_palm_joint" type="fixed">
    <origin xyz="0.0415 -0.003 0" rpy="0 0 0" />
    <parent link="right_wrist_yaw_link" />
    <child link="right_hand_palm_link" />
  </joint>
  <link name="right_hand_palm_link">
    </link>
  <joint name="right_hand_thumb_0_joint" type="revolute">
    <origin xyz="0.0255 0 0" rpy="0 0 0" />
    <axis xyz="0 1 0" />
    <parent link="right_hand_palm_link" />
    <child link="right_hand_thumb_0_link" />
    <limit effort="2.45" velocity="3.14" lower="-1.04719755" upper="1.04719755" />
  </joint>
  <link name="right_hand_thumb_0_link">
    </link>
  <joint name="right_hand_thumb_1_joint" type="revolute">
    <origin xyz="-0.0025 0.0193 0" rpy="0 0 0" />
    <axis xyz="0 0 1" />
    <parent link="right_hand_thumb_0_link" />
    <child link="right_hand_thumb_1_link" />
    <limit effort="1.4" velocity="12" lower="-1.04719755" upper="0.61086523" />
  </joint>
  <link name="right_hand_thumb_1_link">
    </link>
  <joint name="right_hand_thumb_2_joint" type="revolute">
    <origin xyz="0 0.0458 0" rpy="0 0 0" />
    <axis xyz="0 0 1" />
    <parent link="right_hand_thumb_1_link" />
    <child link="right_hand_thumb_2_link" />
    <limit effort="1.4" velocity="12" lower="-1.74532925" upper="0" />
  </joint>
  <link name="right_hand_thumb_2_link">
    </link>
  <joint name="right_hand_middle_0_joint" type="revolute">
    <origin xyz="0.0777 -0.0016 -0.0285" rpy="0 0 0" />
    <axis xyz="0 0 1" />
    <parent link="right_hand_palm_link" />
    <child link="right_hand_middle_0_link" />
    <limit effort="1.4" velocity="12" lower="0" upper="1.57079632" />
  </joint>
  <link name="right_hand_middle_0_link">
    </link>
  <joint name="right_hand_middle_1_joint" type="revolute">
    <origin xyz="0.0458 0 0" rpy="0 0 0" />
    <axis xyz="0 0 1" />
    <parent link="right_hand_middle_0_link" />
    <child link="right_hand_middle_1_link" />
    <limit effort="1.4" velocity="12" lower="0" upper="1.74532925" />
  </joint>
  <link name="right_hand_middle_1_link">
    </link>
  <joint name="right_hand_index_0_joint" type="revolute">
    <origin xyz="0.0777 -0.0016 0.0285" rpy="0 0 0" />
    <axis xyz="0 0 1" />
    <parent link="right_hand_palm_link" />
    <child link="right_hand_index_0_link" />
    <limit effort="1.4" velocity="12" lower="0" upper="1.57079632" />
  </joint>
  <link name="right_hand_index_0_link">
    </link>
  <joint name="right_hand_index_1_joint" type="revolute">
    <origin xyz="0.0458 0 0" rpy="0 0 0" />
    <axis xyz="0 0 1" />
    <parent link="right_hand_index_0_link" />
    <child link="right_hand_index_1_link" />
    <limit effort="1.4" velocity="12" lower="0" upper="1.74532925" />
  </joint>
  <link name="right_hand_index_1_link">
    </link>
</robot>